{
 "cells": [
  {
   "cell_type": "markdown",
   "metadata": {
    "collapsed": true,
    "pycharm": {
     "name": "#%% md\n"
    }
   },
   "source": [
    "### Задание 4 (бонусное)\n",
    "\n",
    "Ваш коллега прислал код функции:\n",
    "```\n",
    "DEFAULT_USER_COUNT = 3\n",
    "\n",
    "def delete_and_return_last_user(region, default_list=[‘A100’, ‘A101’, ‘A102’]):\n",
    "    \"\"“\n",
    "    Удаляет из списка default_list последнего пользователя\n",
    "    и возвращает ID нового последнего пользователя.\n",
    "    ”\"\"\n",
    "    element_to_delete = default_list[-1]\n",
    "    default_list.remove(element_to_delete)\n",
    "\n",
    "    return default_list[DEFAULT_USER_COUNT-2]\n",
    "```\n",
    "При однократном вызове этой функции все работает корректно:\n",
    "```\n",
    "delete_and_return_last_user(1)\n",
    "‘A101’\n",
    "```\n",
    "\n",
    "Однако, при повторном вызове получается ошибка IndexError: list index out of range.\n",
    "\n",
    "Задание:\n",
    "\n",
    "Что значит ошибка list index out of range?\n",
    "Почему при первом запуске функция работает корректно, а при втором - нет?\n",
    "```"
   ]
  },
  {
   "cell_type": "markdown",
   "source": [
    "Это ошибка выхода за пределы массива. В коде есть `default_list` где при вызове удаляется 1 эелемент, количество элементов с 3 уменьшилось до 2. При этом `DEFAULT_USER_COUNT = 3` остается прежним и из-за этого происходит падение при повторном обращении."
   ],
   "metadata": {
    "collapsed": false
   }
  }
 ],
 "metadata": {
  "kernelspec": {
   "display_name": "Python 3",
   "language": "python",
   "name": "python3"
  },
  "language_info": {
   "codemirror_mode": {
    "name": "ipython",
    "version": 2
   },
   "file_extension": ".py",
   "mimetype": "text/x-python",
   "name": "python",
   "nbconvert_exporter": "python",
   "pygments_lexer": "ipython2",
   "version": "2.7.6"
  }
 },
 "nbformat": 4,
 "nbformat_minor": 0
}